<?xml version="1.0" encoding="UTF-8"?>
<testng-results ignored="0" total="6" passed="4" failed="2" skipped="0">
  <reporter-output>
  </reporter-output>
  <suite started-at="2018-07-28T13:07:33Z" name="Suite" finished-at="2018-07-28T13:07:33Z" duration-ms="155">
    <groups>
    </groups>
    <test started-at="2018-07-28T13:07:33Z" name="Test" finished-at="2018-07-28T13:07:33Z" duration-ms="155">
      <class name="maven7.maven7.jay">
        <test-method signature="Tc_4()[pri:0, instance:maven7.maven7.jay@131ef10]" started-at="2018-07-28T13:07:33Z" name="Tc_4" finished-at="2018-07-28T13:07:33Z" duration-ms="3" status="PASS">
          <reporter-output>
          </reporter-output>
        </test-method> <!-- Tc_4 -->
        <test-method signature="Tc_5()[pri:0, instance:maven7.maven7.jay@131ef10]" started-at="2018-07-28T13:07:33Z" name="Tc_5" finished-at="2018-07-28T13:07:33Z" duration-ms="3" status="PASS">
          <reporter-output>
          </reporter-output>
        </test-method> <!-- Tc_5 -->
        <test-method signature="Tc_6()[pri:0, instance:maven7.maven7.jay@131ef10]" started-at="2018-07-28T13:07:33Z" name="Tc_6" finished-at="2018-07-28T13:07:33Z" duration-ms="2" status="FAIL">
          <exception class="java.lang.AssertionError">
            <message>
              <![CDATA[expected [true] but found [false]]]>
            </message>
            <full-stacktrace>
              <![CDATA[java.lang.AssertionError: expected [true] but found [false]
at org.testng.Assert.fail(Assert.java:96)
at org.testng.Assert.failNotEquals(Assert.java:776)
at org.testng.Assert.assertTrue(Assert.java:44)
at org.testng.Assert.assertTrue(Assert.java:54)
at maven7.maven7.jay.Tc_6(jay.java:21)
at java.base/jdk.internal.reflect.NativeMethodAccessorImpl.invoke0(Native Method)
at java.base/jdk.internal.reflect.NativeMethodAccessorImpl.invoke(Unknown Source)
at java.base/jdk.internal.reflect.DelegatingMethodAccessorImpl.invoke(Unknown Source)
at java.base/java.lang.reflect.Method.invoke(Unknown Source)
at org.testng.internal.MethodInvocationHelper.invokeMethod(MethodInvocationHelper.java:124)
at org.testng.internal.Invoker.invokeMethod(Invoker.java:583)
at org.testng.internal.Invoker.invokeTestMethod(Invoker.java:719)
at org.testng.internal.Invoker.invokeTestMethods(Invoker.java:989)
at org.testng.internal.TestMethodWorker.invokeTestMethods(TestMethodWorker.java:125)
at org.testng.internal.TestMethodWorker.run(TestMethodWorker.java:109)
at org.testng.TestRunner.privateRun(TestRunner.java:648)
at org.testng.TestRunner.run(TestRunner.java:505)
at org.testng.SuiteRunner.runTest(SuiteRunner.java:455)
at org.testng.SuiteRunner.runSequentially(SuiteRunner.java:450)
at org.testng.SuiteRunner.privateRun(SuiteRunner.java:415)
at org.testng.SuiteRunner.run(SuiteRunner.java:364)
at org.testng.SuiteRunnerWorker.runSuite(SuiteRunnerWorker.java:52)
at org.testng.SuiteRunnerWorker.run(SuiteRunnerWorker.java:84)
at org.testng.TestNG.runSuitesSequentially(TestNG.java:1208)
at org.testng.TestNG.runSuitesLocally(TestNG.java:1137)
at org.testng.TestNG.runSuites(TestNG.java:1049)
at org.testng.TestNG.run(TestNG.java:1017)
at org.testng.remote.AbstractRemoteTestNG.run(AbstractRemoteTestNG.java:114)
at org.testng.remote.RemoteTestNG.initAndRun(RemoteTestNG.java:251)
at org.testng.remote.RemoteTestNG.main(RemoteTestNG.java:77)
]]>
            </full-stacktrace>
          </exception> <!-- java.lang.AssertionError -->
          <reporter-output>
          </reporter-output>
        </test-method> <!-- Tc_6 -->
      </class> <!-- maven7.maven7.jay -->
      <class name="maven7.maven7.jay2">
        <test-method signature="Tc_1()[pri:0, instance:maven7.maven7.jay2@7bedc48a]" started-at="2018-07-28T13:07:33Z" name="Tc_1" finished-at="2018-07-28T13:07:33Z" duration-ms="26" status="PASS">
          <reporter-output>
          </reporter-output>
        </test-method> <!-- Tc_1 -->
        <test-method signature="Tc_2()[pri:0, instance:maven7.maven7.jay2@7bedc48a]" started-at="2018-07-28T13:07:33Z" name="Tc_2" finished-at="2018-07-28T13:07:33Z" duration-ms="4" status="PASS">
          <reporter-output>
          </reporter-output>
        </test-method> <!-- Tc_2 -->
        <test-method signature="Tc_3()[pri:0, instance:maven7.maven7.jay2@7bedc48a]" started-at="2018-07-28T13:07:33Z" name="Tc_3" finished-at="2018-07-28T13:07:33Z" duration-ms="4" status="FAIL">
          <exception class="java.lang.AssertionError">
            <message>
              <![CDATA[expected [true] but found [false]]]>
            </message>
            <full-stacktrace>
              <![CDATA[java.lang.AssertionError: expected [true] but found [false]
at org.testng.Assert.fail(Assert.java:96)
at org.testng.Assert.failNotEquals(Assert.java:776)
at org.testng.Assert.assertTrue(Assert.java:44)
at org.testng.Assert.assertTrue(Assert.java:54)
at maven7.maven7.jay2.Tc_3(jay2.java:21)
at java.base/jdk.internal.reflect.NativeMethodAccessorImpl.invoke0(Native Method)
at java.base/jdk.internal.reflect.NativeMethodAccessorImpl.invoke(Unknown Source)
at java.base/jdk.internal.reflect.DelegatingMethodAccessorImpl.invoke(Unknown Source)
at java.base/java.lang.reflect.Method.invoke(Unknown Source)
at org.testng.internal.MethodInvocationHelper.invokeMethod(MethodInvocationHelper.java:124)
at org.testng.internal.Invoker.invokeMethod(Invoker.java:583)
at org.testng.internal.Invoker.invokeTestMethod(Invoker.java:719)
at org.testng.internal.Invoker.invokeTestMethods(Invoker.java:989)
at org.testng.internal.TestMethodWorker.invokeTestMethods(TestMethodWorker.java:125)
at org.testng.internal.TestMethodWorker.run(TestMethodWorker.java:109)
at org.testng.TestRunner.privateRun(TestRunner.java:648)
at org.testng.TestRunner.run(TestRunner.java:505)
at org.testng.SuiteRunner.runTest(SuiteRunner.java:455)
at org.testng.SuiteRunner.runSequentially(SuiteRunner.java:450)
at org.testng.SuiteRunner.privateRun(SuiteRunner.java:415)
at org.testng.SuiteRunner.run(SuiteRunner.java:364)
at org.testng.SuiteRunnerWorker.runSuite(SuiteRunnerWorker.java:52)
at org.testng.SuiteRunnerWorker.run(SuiteRunnerWorker.java:84)
at org.testng.TestNG.runSuitesSequentially(TestNG.java:1208)
at org.testng.TestNG.runSuitesLocally(TestNG.java:1137)
at org.testng.TestNG.runSuites(TestNG.java:1049)
at org.testng.TestNG.run(TestNG.java:1017)
at org.testng.remote.AbstractRemoteTestNG.run(AbstractRemoteTestNG.java:114)
at org.testng.remote.RemoteTestNG.initAndRun(RemoteTestNG.java:251)
at org.testng.remote.RemoteTestNG.main(RemoteTestNG.java:77)
]]>
            </full-stacktrace>
          </exception> <!-- java.lang.AssertionError -->
          <reporter-output>
          </reporter-output>
        </test-method> <!-- Tc_3 -->
      </class> <!-- maven7.maven7.jay2 -->
    </test> <!-- Test -->
  </suite> <!-- Suite -->
</testng-results>
